Workbook
Name Balance_Sheet: 'Historical FS'!$B$48:$M$67
Name Cash_Flow_Statements: 'Historical FS'!$B$71
Name Cashflow_statement: 'Historical FS'!$B$71:$M$108
Name Income_Statement: 'Historical FS'!$B$5:$M$45

Sheet Data Sheet
A1: COMPANY NAME | B1: TATA MOTORS LTD | E1: =IF(B2<>B3, "A NEW VERSION OF THE WORKSHEET IS AVAILABLE", "")
A2: LATEST VERSION | B2: 2.1 | E2: PLEASE DO NOT MAKE ANY CHANGES TO THIS SHEET
A3: CURRENT VERSION | B3: 2.1
A5: META
A6: Number of shares | B6: =IF(B9>0, B9/B8, 0) -> 368.11892
A7: Face Value | B7: 2
A8: Current Price | B8: 680.65
A9: Market Capitalization | B9: 250560.14
A15: PROFIT & LOSS
A16: Report Date | B16: 42094 | C16: 42460 | D16: 42825 | E16: 43190 | F16: 43555 | G16: 43921 | H16: 44286 | I16: 44651 | J16: 45016 | K16: 45382
A17: Sales | B17: 263158.98 | C17: 273045.6 | D17: 269692.51 | E17: 291550.48 | F17: 301938.4 | G17: 261067.97 | H17: 249794.75 | I17: 278453.62 | J17: 345966.97 | K17: 437927.77
A18: Raw Material Cost | B18: 163250.36 | C18: 166134.01 | D18: 173294.08 | E18: 187896.58 | F18: 194267.91 | G18: 164899.82 | H18: 153607.36 | I18: 179295.33 | J18: 231251.26 | K18: 274321.23
A19: Change in Inventory | B19: 3330.35 | C19: 2750.99 | D19: 7399.92 | E19: 2046.58 | F19: -2053.28 | G19: -2231.19 | H19: -4684.16 | I19: -1590.49 | J19: 4781.62 | K19: 1565.53
A20: Power and Fuel | B20: 1121.75 | C20: 1143.63 | D20: 1159.82 | E20: 1308.08 | F20: 1585.93 | G20: 1264.95 | H20: 1112.87 | I20: 2178.29 | J20: 2513.33 | K20: 2195.12
A21: Other Mfr. Exp | B21: 16173.17 | C21: 12101.53 | D21: 10067.37 | E21: 10971.66 | F21: 11694.54 | G21: 11541.51 | H21: 8273.17 | I21: 9427.38 | J21: 11765.97 | K21: 17114.33
A22: Employee Cost | B22: 25641.95 | C22: 28880.89 | D22: 28332.89 | E22: 30300.09 | F22: 33243.87 | G22: 30438.6 | H22: 27648.48 | I22: 30808.52 | J22: 33654.7 | K22: 42486.64
A23: Selling and admin | B23: 23603.01 | C23: 21991.9 | D23: 30039.38 | E23: 31004.58 | F23: 32719.8 | G23: 29248.32 | H23: 23015.79 | I23: 29205.4 | J23: 34839.19 | K23: 42765.33
A24: Other Expenses | B24: -2539.56 | C24: 7149.38 | D24: 4610.2 | E24: 658.39 | F24: 1708.74 | G24: 3456.51 | H24: -834.51 | I24: 1228.12 | J24: 4908.34 | K24: 1072.31
A25: Other Income | B25: 714.03 | C25: -2669.62 | D25: 1869.1 | E25: 5932.73 | F25: -26686.25 | G25: 101.71 | H25: -11117.83 | I25: 2424.05 | J25: 6663.97 | K25: 5672.66
A26: Depreciation | B26: 13388.63 | C26: 16710.78 | D26: 17904.99 | E26: 21553.59 | F26: 23590.63 | G26: 21425.43 | H26: 23546.71 | I26: 24835.69 | J26: 24860.36 | K26: 27270.13
A27: Interest | B27: 4861.49 | C27: 4889.08 | D27: 4238.01 | E27: 4681.79 | F27: 5758.6 | G27: 7243.33 | H27: 8097.17 | I27: 9311.86 | J27: 10225.48 | K27: 9985.76
... A30: Net profit | B30: 13986.29 | C30: 11579.31 | D30: 7454.36 | E30: 8988.91 | F30: -28826.23 | G30: -12070.85 | H30: -13451.39 | I30: -11441.47 | J30: 2414.29 | K30: 31399.09
A31: Dividend Amount | C31: 67.92 | J31: 766.02 | K31: 2299.5
B34: =B30+B26+B27+B29 -> 39879.32 | C34: =C30+C26+C27+C29 -> 36204.22 | D34: =D30+D26+D27+D29 -> 32848.59 | E34: =E30+E26+E27+E29 -> 39566.22 | F34: =F30+F26+F27+F29 -> -1914.45 | G34: =G30+G26+G27+G29 -> 16993.16 | H34: =H30+H26+H27+H29 -> 20734.35 | I34: =I30+I26+I27+I29 -> 26937.37 | ... K34: =K30+K26+K27+K29 -> 64803.34
A35: EBIT | B35: =B30+B27+B29 -> 26490.69 | C35: =C30+C27+C29 -> 19493.44 | D35: =D30+D27+D29 -> 14943.6 | E35: =E30+E27+E29 -> 18012.63 | F35: =F30+F27+F29 -> -25505.08 | G35: =G30+G27+G29 -> -4432.27 | H35: =H30+H27+H29 -> -2812.36 | I35: =I30+I27+I29 -> 2101.68 | ... K35: =K30+K27+K29 -> 37533.21
A39: Quarters
A40: Report Date | B40: 44834 | C40: 44926 | D40: 45016 | E40: 45107 | F40: 45199 | G40: 45291 | H40: 45382 | I40: 45473 | J40: 45565 | K40: 45657
A41: Sales | B41: 79611.37 | C41: 88488.59 | D41: 105932.35 | E41: 102236 | F41: 105129 | G41: 110577 | H41: 119986 | I41: 108048 | J41: 101450 | K41: 113575
A42: Expenses | B42: 74039.06 | C42: 77668.35 | D42: 92817.95 | E42: 89019 | F42: 91362 | G42: 95159 | H42: 102851 | I42: 92263 | J42: 89291 | K42: 100532
A43: Other Income | B43: 1351.14 | C43: 1129.98 | D43: 1452.86 | E43: 895 | F43: 1557 | G43: 1604 | H43: 1619 | I43: 1747 | J43: 1647 | K43: 1764
A44: Depreciation | B44: 5897.34 | C44: 6071.78 | D44: 7050.2 | E44: 6633 | F44: 6637 | G44: 6850 | H44: 7151 | I44: 6574 | J44: 6005 | K44: 5408
A45: Interest | B45: 2487.26 | C45: 2675.83 | D45: 2641.67 | E45: 2615 | F45: 2652 | G45: 2485 | H45: 2234 | I45: 2088 | J45: 2034 | K45: 1725
A46: Profit before tax | B46: -1461.15 | C46: 3202.61 | D46: 4875.39 | E46: 4864 | F46: 6035 | G46: 7687 | H46: 9369 | I46: 8870 | J46: 5767 | K46: 7674
A47: Tax | B47: -457.08 | C47: 262.83 | D47: -620.65 | E47: 1563 | F47: 2203 | G47: 542 | H47: -8160 | I47: 3178 | J47: 2317 | K47: 2096
A48: Net profit | B48: -944.61 | C48: 2957.71 | D48: 5407.79 | E48: 3203 | F48: 3764 | G48: 7025 | H48: 17407 | I48: 5566 | J48: 3343 | K48: 5451
A49: Operating Profit | B49: 5572.31 | C49: 10820.24 | D49: 13114.4 | E49: 13217 | F49: 13767 | G49: 15418 | H49: 17135 | I49: 15785 | J49: 12159 | K49: 13043
A54: BALANCE SHEET
A55: Report Date | B55: 42094 | C55: 42460 | D55: 42825 | E55: 43190 | F55: 43555 | G55: 43921 | H55: 44286 | I55: 44651 | J55: 45016 | K55: 45382
A56: Equity Share Capital | B56: 643.78 | C56: 679.18 | D56: 679.22 | E56: 679.22 | F56: 679.22 | G56: 719.54 | H56: 765.81 | I56: 765.88 | J56: 766.02 | K56: 766.5
A57: Reserves | B57: 55618.14 | C57: 78273.23 | D57: 57382.67 | E57: 94748.69 | F57: 59500.34 | G57: 62358.99 | H57: 54480.91 | I57: 43795.36 | J57: 44555.77 | K57: 84151.52
...

Sheet Cash Flow Data
C2: 42064 | D2: 42430 | E2: 42795 | F2: 43160 | G2: 43525 | H2: 43891 | I2: 44256 | J2: 44621 | K2: 44986 | L2: 45352
B3: Cash from Operating Activity - | C3: 35531 | D3: 37900 | E3: 30199 | F3: 23857 | G3: 18891 | H3: 26633 | I3: 29001 | J3: 14283 | K3: 35388 | L3: 67915
B4: Profit from operations | C4: 43397 | D4: 38626 | E4: 28840 | F4: 33312 | G4: 28771 | H4: 23352 | I4: 31198 | J4: 26943 | K4: 41694 | L4: 65106
B5: Receivables | C5: -3179 | D5: -2223 | E5: -4152 | F5: -10688 | G5: -9109 | H5: 9950 | I5: -5505 | J5: 185 | K5: -2213 | L5: -1875
B6: Inventory | C6: -3692 | D6: -5743 | E6: -6621 | F6: -3560 | G6: 2069 | H6: 2326 | I6: 3814 | J6: 472 | K6: -5665 | L6: -7265
B7: Payables | C7: 3598 | D7: 3947 | E7: 9301 | F7: 7320 | G7: -4692 | H7: -8085 | I7: 5748 | J7: -7012 | K7: 6945 | L7: 13706
B8: Loans Advances | C8: 0 | D8: -520 | E8: 0 | F8: 0 | G8: 0 | H8: 0 | I8: 0 | J8: 0 | K8: 0 | L8: 0
B9: Other WC items | C9: -398 | D9: 5852 | E9: 4727 | F9: 494 | G9: 4512 | H9: 875 | I9: -4150 | J9: -4396 | K9: -2194 | L9: 2760
B10: Working capital changes | C10: -3672 | D10: 1313 | E10: 3254 | F10: -6434 | G10: -7221 | H10: 5065 | I10: -93 | J10: -10750 | K10: -3127 | L10: 7325
B11: Direct taxes | C11: -4194 | D11: -2040 | E11: -1895 | F11: -3021 | G11: -2659 | H11: -1785 | I11: -2105 | J11: -1910 | K11: -3179 | L11: -4516
B12: Cash from Investing Activity - | C12: -36232 | D12: -36694 | E12: -39571 | F12: -25139 | G12: -20878 | H12: -33115 | I12: -25672 | J12: -4444 | K12: -15417 | L12: -22782
B13: Fixed assets purchased | C13: -31962 | D13: -31503 | E13: -16072 | F13: -35079 | G13: -35304 | H13: -29702 | I13: -20205 | J13: -15168 | K13: -19230 | L13: -31414
B14: Fixed assets sold | C14: 74 | D14: 59 | E14: 53 | F14: 30 | G14: 67 | H14: 171 | I14: 351 | J14: 230 | K14: 285 | L14: 231
... B33: Net Cash Flow | C33: 4500 | D33: -2589 | E33: -3167 | F33: 730 | G33: 6843 | H33: -3092 | I33: 13232 | J33: 6459 | K33: -6272 | L33: 8128

Sheet Historical FS
B2: ="Historical Financial Statement - "&'Data Sheet'!B1 -> Historical Financial Statement - TATA MOTORS LTD
B3: Year | C3: ='Data Sheet'!B16 -> 42094 | D3: ='Data Sheet'!C16 -> 42460 | E3: ='Data Sheet'!D16 -> 42825 | F3: ='Data Sheet'!E16 -> 43190 | G3: ='Data Sheet'!F16 -> 43555 | H3: ='Data Sheet'!G16 -> 43921 | I3: ='Data Sheet'!H16 -> 44286 | J3: ='Data Sheet'!I16 -> 44651 | ... L3: ='Data Sheet'!K16 -> 45382 | M3: LTM
A5: # | B5: Income Statement | C5: 42094 | D5: 42460 | E5: 42825 | F5: 43190 | G5: 43555 | H5: 43921 | I5: 44286 | J5: 44651 | K5: 45016 | L5: 45382 | M5: LTM
B6: Sales | C6: =IFERROR('Data Sheet'!B17,0) -> 263158.98 | D6: =IFERROR('Data Sheet'!C17,0) -> 273045.6 | E6: =IFERROR('Data Sheet'!D17,0) -> 269692.51 | F6: =IFERROR('Data Sheet'!E17,0) -> 291550.48 | G6: =IFERROR('Data Sheet'!F17,0) -> 301938.4 | H6: =IFERROR('Data Sheet'!G17,0) -> 261067.97 | I6: =IFERROR('Data Sheet'!H17,0) -> 249794.75 | J6: =IFERROR('Data Sheet'!I17,0) -> 278453.62 | ... L6: =IFERROR('Data Sheet'!K17,0) -> 437927.77 | M6: =IFERROR(SUM('Data Sheet'!H41:K41),0) -> 443059
B7: Sales Growth | C7: - | D7: =D6/C6-1 -> 0.037569001 | E7: =E6/D6-1 -> -0.01228033 | F7: =F6/E6-1 -> 0.081047746 | G7: =G6/F6-1 -> 0.035629919 | H7: =H6/G6-1 -> -0.13536016 | I7: =I6/H6-1 -> -0.043181168 | J7: =J6/I6-1 -> 0.11472967 | K7: =K6/J6-1 -> 0.24245815 | ... M7: =M6/L6-1 -> 0.011717069
B9: COGS | C9: =IFERROR(SUM('Data Sheet'!B18,'Data Sheet'!B20:B22,-1*'Data Sheet'!B19),0) -> 202856.88 | D9: =IFERROR(SUM('Data Sheet'!C18,'Data Sheet'!C20:C22,-1*'Data Sheet'!C19),0) -> 205509.07 | E9: =IFERROR(SUM('Data Sheet'!D18,'Data Sheet'!D20:D22,-1*'Data Sheet'!D19),0) -> 205454.24 | F9: =IFERROR(SUM('Data Sheet'!E18,'Data Sheet'!E20:E22,-1*'Data Sheet'!E19),0) -> 228429.83 | G9: =IFERROR(SUM('Data Sheet'!F18,'Data Sheet'!F20:F22,-1*'Data Sheet'!F19),0) -> 242845.53 | H9: =IFERROR(SUM('Data Sheet'!G18,'Data Sheet'!G20:G22,-1*'Data Sheet'!G19),0) -> 210376.07 | I9: =IFERROR(SUM('Data Sheet'!H18,'Data Sheet'!H20:H22,-1*'Data Sheet'!H19),0) -> 195326.04 | J9: =IFERROR(SUM('Data Sheet'!I18,'Data Sheet'!I20:I22,-1*'Data Sheet'!I19),0) -> 223300.01 | ... L9: =IFERROR(SUM('Data Sheet'!K18,'Data Sheet'!K20:K22,-1*'Data Sheet'!K19),0) -> 334551.79 | M9: =IFERROR(SUM('Data Sheet'!H42:K42),0) -> 384937
B10: COGS % of Sales | C10: =C9/C6 -> 0.77085297 | D10: =D9/D6 -> 0.75265476 | E10: =E9/E6 -> 0.76180922 | F10: =F9/F6 -> 0.7835001 | G10: =G9/G6 -> 0.80428833 | H10: =H9/H6 -> 0.80582873 | I10: =I9/I6 -> 0.78194614 | J10: =J9/J6 -> 0.80192892 | ... M10: =M9/M6 -> 0.86881657
B12: Gross Profit | C12: =C6-C9 -> 60302.1 | D12: =D6-D9 -> 67536.53 | E12: =E6-E9 -> 64238.27 | F12: =F6-F9 -> 63120.65 | G12: =G6-G9 -> 59092.87 | H12: =H6-H9 -> 50691.9 | I12: =I6-I9 -> 54468.71 | J12: =J6-J9 -> 55153.61 | ... M12: =M6-M9 -> 58122
B13: Gross Margin | C13: =C12/C6 -> 0.22914703 | D13: =D12/D6 -> 0.24734524 | E13: =E12/E6 -> 0.23819078 | F13: =F12/F6 -> 0.2164999 | G13: =G12/G6 -> 0.19571167 | H13: =H12/H6 -> 0.19417127 | I13: =I12/I6 -> 0.21805386 | J13: =J12/J6 -> 0.19807108 | ... M13: =M12/M6 -> 0.13118343
B15: Selling & General Expenses | C15: =IFERROR(SUM('Data Sheet'!B23:B24),0) -> 21063.45 | D15: =IFERROR(SUM('Data Sheet'!C23:C24),0) -> 29141.28 | E15: =IFERROR(SUM('Data Sheet'!D23:D24),0) -> 34649.58 | F15: =IFERROR(SUM('Data Sheet'!E23:E24),0) -> 31662.97 | G15: =IFERROR(SUM('Data Sheet'!F23:F24),0) -> 34428.54 | H15: =IFERROR(SUM('Data Sheet'!G23:G24),0) -> 32704.83 | I15: =IFERROR(SUM('Data Sheet'!H23:H24),0) -> 22181.28 | J15: =IFERROR(SUM('Data Sheet'!I23:I24),0) -> 30433.52 | ... M15: =IFERROR(SUM('Data Sheet'!L23:L24),0) -> 0
B16: S&G % of Sales | C16: =C15/C6 -> 0.08004078 | D16: =D15/D6 -> 0.10672679 | E16: =E15/E6 -> 0.1284781 | F16: =F15/F6 -> 0.10860202 | G16: =G15/G6 -> 0.11402505 | H16: =H15/H6 -> 0.12527324 | I16: =I15/I6 -> 0.088798023 | J16: =J15/J6 -> 0.10929475 | ... M16: =M15/M6 -> 0
B18: EBITDA | C18: =C12-C15 -> 39238.65 | D18: =D12-D15 -> 38395.25 | E18: =E12-E15 -> 29588.69 | F18: =F12-F15 -> 31457.68 | G18: =G12-G15 -> 24664.33 | H18: =H12-H15 -> 17987.07 | I18: =I12-I15 -> 32287.43 | J18: =J12-J15 -> 24720.09 | ... M18: =M12-M15 -> 58122
B19: EBITDA % of Sales | C19: =C18/C6 -> 0.14910626 | D19: =D18/D6 -> 0.14061845 | E19: =E18/E6 -> 0.10971269 | F19: =F18/F6 -> 0.10789788 | G19: =G18/G6 -> 0.081686629 | H19: =H18/H6 -> 0.068898034 | I19: =I18/I6 -> 0.12925584 | J19: =J18/J6 -> 0.088776328 | ... M19: =M18/M6 -> 0.13118343
B21: Interest | C21: =IFERROR('Data Sheet'!B27,0) -> 4861.49 | D21: =IFERROR('Data Sheet'!C27,0) -> 4889.08 | E21: =IFERROR('Data Sheet'!D27,0) -> 4238.01 | F21: =IFERROR('Data Sheet'!E27,0) -> 4681.79 | G21: =IFERROR('Data Sheet'!F27,0) -> 5758.6 | H21: =IFERROR('Data Sheet'!G27,0) -> 7243.33 | I21: =IFERROR('Data Sheet'!H27,0) -> 8097.17 | J21: =IFERROR('Data Sheet'!I27,0) -> 9311.86 | ... L21: =IFERROR('Data Sheet'!K27,0) -> 9985.76 | M21: =IFERROR(SUM('Data Sheet'!H45:K45),0) -> 8081
B22: Interest % of Sales | C22: =C21/C6 -> 0.018473586 | D22: =D21/D6 -> 0.017905727 | E22: =E21/E6 -> 0.01571423 | F22: =F21/F6 -> 0.016058248 | G22: =G21/G6 -> 0.019072102 | H22: =H21/H6 -> 0.027744997 | I22: =I21/I6 -> 0.032415293 | J22: =J21/J6 -> 0.033441332 | ... M22: =M21/M6 -> 0.018239106
B24: Depreciation | C24: =IFERROR('Data Sheet'!B26,0) -> 13388.63 | D24: =IFERROR('Data Sheet'!C26,0) -> 16710.78 | E24: =IFERROR('Data Sheet'!D26,0) -> 17904.99 | F24: =IFERROR('Data Sheet'!E26,0) -> 21553.59 | G24: =IFERROR('Data Sheet'!F26,0) -> 23590.63 | H24: =IFERROR('Data Sheet'!G26,0) -> 21425.43 | I24: =IFERROR('Data Sheet'!H26,0) -> 23546.71 | J24: =IFERROR('Data Sheet'!I26,0) -> 24835.69 | ... L24: =IFERROR('Data Sheet'!K26,0) -> 27270.13 | M24: =IFERROR(SUM('Data Sheet'!H44:K44),0) -> 25138
B25: Depreciation of Sales | C25: =C24/C6 -> 0.050876584 | D25: =D24/D6 -> 0.061201426 | E25: =E24/E6 -> 0.066390387 | F25: =F24/F6 -> 0.073927472 | G25: =G24/G6 -> 0.078130605 | H25: =H24/H6 -> 0.082068398 | I25: =I24/I6 -> 0.094264231 | J25: =J24/J6 -> 0.089191478 | ... M25: =M24/M6 -> 0.056737365
B27: Earning Before Tax (EBT) | C27: =IFERROR(C18-SUM(C21,C24),0) -> 20988.53 | D27: =IFERROR(D18-SUM(D21,D24),0) -> 16795.39 | E27: =IFERROR(E18-SUM(E21,E24),0) -> 7445.69 | F27: =IFERROR(F18-SUM(F21,F24),0) -> 5222.3 | G27: =IFERROR(G18-SUM(G21,G24),0) -> -4684.9 | H27: =IFERROR(H18-SUM(H21,H24),0) -> -10681.69 | I27: =IFERROR(I18-SUM(I21,I24),0) -> 643.55 | J27: =IFERROR(J18-SUM(J21,J24),0) -> -9427.46 | ... M27: =IFERROR(M18-SUM(M21,M24),0) -> 24903
B28: EBT % of Sales | C28: =C27/C6 -> 0.079756085 | D28: =D27/D6 -> 0.061511301 | E28: =E27/E6 -> 0.027608071 | F28: =F27/F6 -> 0.017912164 | G28: =G27/G6 -> -0.015516079 | H28: =H27/H6 -> -0.04091536 | I28: =I27/I6 -> 0.0025763152 | J28: =J27/J6 -> -0.033856482 | ... M28: =M27/M6 -> 0.056206961
B30: Tax | C30: =IFERROR('Data Sheet'!B29,0) -> 7642.91 | D30: =IFERROR('Data Sheet'!C29,0) -> 3025.05 | E30: =IFERROR('Data Sheet'!D29,0) -> 3251.23 | F30: =IFERROR('Data Sheet'!E29,0) -> 4341.93 | G30: =IFERROR('Data Sheet'!F29,0) -> -2437.45 | H30: =IFERROR('Data Sheet'!G29,0) -> 395.25 | I30: =IFERROR('Data Sheet'!H29,0) -> 2541.86 | J30: =IFERROR('Data Sheet'!I29,0) -> 4231.29 | ... L30: =IFERROR('Data Sheet'!K29,0) -> -3851.64 | M30: =IFERROR(SUM('Data Sheet'!H47:K47),0) -> -569
B31: Effective Tax Rate | C31: =C30/C27 -> 0.36414699 | D31: =D30/D27 -> 0.18011192 | E31: =E30/E27 -> 0.43665933 | F31: =F30/F27 -> 0.83142102 | G31: =G30/G27 -> 0.52027791 | H31: =H30/H27 -> -0.037002572 | I31: =I30/I27 -> 3.9497475 | J31: =J30/J27 -> -0.44882609 | ... M31: =M30/M27 -> -0.022848653
B33: Net Profit | C33: =IFERROR(C27-C30,0) -> 13345.62 | D33: =IFERROR(D27-D30,0) -> 13770.34 | E33: =IFERROR(E27-E30,0) -> 4194.46 | F33: =IFERROR(F27-F30,0) -> 880.37 | G33: =IFERROR(G27-G30,0) -> -2247.45 | H33: =IFERROR(H27-H30,0) -> -11076.94 | I33: =IFERROR(I27-I30,0) -> -1898.31 | J33: =IFERROR(J27-J30,0) -> -13658.75 | ... M33: =IFERROR(M27-M30,0) -> 25472
B34: Net Margin | C34: =C33/C6 -> 0.050713147 | D34: =D33/D6 -> 0.050432382 | E34: =E33/E6 -> 0.015552749 | F34: =F33/F6 -> 0.0030196143 | G34: =G33/G6 -> -0.0074434057 | H34: =H33/H6 -> -0.042429334 | I34: =I33/I6 -> -0.0075994792 | J34: =J33/J6 -> -0.049052155 | ... M34: =M33/M6 -> 0.057491214
B36: No. Of Equity Shares | C36: =IFERROR('Data Sheet'!B92,0) -> 288.74 | D36: =IFERROR('Data Sheet'!C92,0) -> 288.72 | E36: =IFERROR('Data Sheet'!D92,0) -> 288.73 | F36: =IFERROR('Data Sheet'!E92,0) -> 288.73 | G36: =IFERROR('Data Sheet'!F92,0) -> 288.73 | H36: =IFERROR('Data Sheet'!G92,0) -> 308.9 | I36: =IFERROR('Data Sheet'!H92,0) -> 332.03 | J36: =IFERROR('Data Sheet'!I92,0) -> 332.07 | ... L36: =IFERROR('Data Sheet'!K92,0) -> 332.37 | M36: 332.37
B39: Earning Per Share | C39: =IFERROR(C33/C36,0) -> 46.220198 | D39: =IFERROR(D33/D36,0) -> 47.694444 | E39: =IFERROR(E33/E36,0) -> 14.527275 | F39: =IFERROR(F33/F36,0) -> 3.0491116 | G39: =IFERROR(G33/G36,0) -> -7.7839158 | H39: =IFERROR(H33/H36,0) -> -35.859307 | I39: =IFERROR(I33/I36,0) -> -5.7172846 | J39: =IFERROR(J33/J36,0) -> -41.132141 | ... M39: =IFERROR(M33/M36,0) -> 76.637482
B40: EPS Growth % | D40: =IFERROR(D39/C39-1,0) -> 0.031896149 | E40: =IFERROR(E39/D39-1,0) -> -0.6954095 | F40: =IFERROR(F39/E39-1,0) -> -0.79011124 | G40: =IFERROR(G39/F39-1,0) -> -3.5528471 | H40: =IFERROR(H39/G39-1,0) -> 3.6068468 | I40: =IFERROR(I39/H39-1,0) -> -0.84056344 | J40: =IFERROR(J39/I39-1,0) -> 6.194349 | K40: =IFERROR(K39/J39-1,0) -> -0.70909622 | ... M40: =IFERROR(M39/L39-1,0) -> -0.025334343
B42: Dividend Per Share | C42: =IFERROR('Data Sheet'!B31/'Historical FS'!C36,0) -> 0 | D42: =IFERROR('Data Sheet'!C31/'Historical FS'!D36,0) -> 0.23524522 | E42: =IFERROR('Data Sheet'!D31/'Historical FS'!E36,0) -> 0 | F42: =IFERROR('Data Sheet'!E31/'Historical FS'!F36,0) -> 0 | G42: =IFERROR('Data Sheet'!F31/'Historical FS'!G36,0) -> 0 | H42: =IFERROR('Data Sheet'!G31/'Historical FS'!H36,0) -> 0 | I42: =IFERROR('Data Sheet'!H31/'Historical FS'!I36,0) -> 0 | J42: =IFERROR('Data Sheet'!I31/'Historical FS'!J36,0) -> 0 | ... M42: =IFERROR('Data Sheet'!L31/'Historical FS'!M36,0) -> 0
B43: Dividend Payout Ratio | C43: =IFERROR(C42/C39,0) -> 0 | D43: =IFERROR(D42/D39,0) -> 0.0049323401 | E43: =IFERROR(E42/E39,0) -> 0 | F43: =IFERROR(F42/F39,0) -> 0 | G43: =IFERROR(G42/G39,0) -> 0 | H43: =IFERROR(H42/H39,0) -> 0 | I43: =IFERROR(I42/I39,0) -> 0 | J43: =IFERROR(J42/J39,0) -> 0 | ... M43: =IFERROR(M42/M39,0) -> 0
B45: Retained Earnings | C45: =IFERROR(IF(C39>C42,1-C43,0),0) -> 1 | D45: =IFERROR(IF(D39>D42,1-D43,0),0) -> 0.99506766 | E45: =IFERROR(IF(E39>E42,1-E43,0),0) -> 1 | F45: =IFERROR(IF(F39>F42,1-F43,0),0) -> 1 | G45: =IFERROR(IF(G39>G42,1-G43,0),0) -> 0 | H45: =IFERROR(IF(H39>H42,1-H43,0),0) -> 0 | I45: =IFERROR(IF(I39>I42,1-I43,0),0) -> 0 | J45: =IFERROR(IF(J39>J42,1-J43,0),0) -> 0 | ... M45: =IFERROR(IF(M39>M42,1-M43,0),0) -> 1
A48: # | B48: Balance Sheet | C48: 42094 | D48: 42460 | E48: 42825 | F48: 43190 | G48: 43555 | H48: 43921 | I48: 44286 | J48: 44651 | K48: 45016 | L48: 45382 | M48: LTM
B50: Equity Share Capital | C50: =IFERROR('Data Sheet'!B56,0) -> 643.78 | D50: =IFERROR('Data Sheet'!C56,0) -> 679.18 | E50: =IFERROR('Data Sheet'!D56,0) -> 679.22 | F50: =IFERROR('Data Sheet'!E56,0) -> 679.22 | G50: =IFERROR('Data Sheet'!F56,0) -> 679.22 | H50: =IFERROR('Data Sheet'!G56,0) -> 719.54 | I50: =IFERROR('Data Sheet'!H56,0) -> 765.81 | J50: =IFERROR('Data Sheet'!I56,0) -> 765.88 | ... L50: =IFERROR('Data Sheet'!K56,0) -> 766.5
B51: Reserves | C51: =IFERROR('Data Sheet'!B57,0) -> 55618.14 | D51: =IFERROR('Data Sheet'!C57,0) -> 78273.23 | E51: =IFERROR('Data Sheet'!D57,0) -> 57382.67 | F51: =IFERROR('Data Sheet'!E57,0) -> 94748.69 | G51: =IFERROR('Data Sheet'!F57,0) -> 59500.34 | H51: =IFERROR('Data Sheet'!G57,0) -> 62358.99 | I51: =IFERROR('Data Sheet'!H57,0) -> 54480.91 | J51: =IFERROR('Data Sheet'!I57,0) -> 43795.36 | ... L51: =IFERROR('Data Sheet'!K57,0) -> 84151.52
B52: Borrowings | C52: =IFERROR('Data Sheet'!B58,0) -> 73610.39 | D52: =IFERROR('Data Sheet'!C58,0) -> 69359.96 | E52: =IFERROR('Data Sheet'!D58,0) -> 78603.98 | F52: =IFERROR('Data Sheet'!E58,0) -> 88950.47 | G52: =IFERROR('Data Sheet'!F58,0) -> 106175.34 | H52: =IFERROR('Data Sheet'!G58,0) -> 124787.64 | I52: =IFERROR('Data Sheet'!H58,0) -> 142130.57 | J52: =IFERROR('Data Sheet'!I58,0) -> 146449.03 | ... L52: =IFERROR('Data Sheet'!K58,0) -> 107262.5
B53: Other Liabilities | C53: =IFERROR('Data Sheet'!B59,0) -> 107442.48 | D53: =IFERROR('Data Sheet'!C59,0) -> 114871.75 | E53: =IFERROR('Data Sheet'!D59,0) -> 135914.49 | F53: =IFERROR('Data Sheet'!E59,0) -> 142813.43 | G53: =IFERROR('Data Sheet'!F59,0) -> 139348.59 | H53: =IFERROR('Data Sheet'!G59,0) -> 132313.22 | I53: =IFERROR('Data Sheet'!H59,0) -> 144192.62 | J53: =IFERROR('Data Sheet'!I59,0) -> 138051.22 | ... L53: =IFERROR('Data Sheet'!K59,0) -> 177340.09
B54: Total Liabilities | C54: =IFERROR('Data Sheet'!B60,0) -> 237314.79 | D54: =IFERROR('Data Sheet'!C60,0) -> 263184.12 | E54: =IFERROR('Data Sheet'!D60,0) -> 272580.36 | F54: =IFERROR('Data Sheet'!E60,0) -> 327191.81 | G54: =IFERROR('Data Sheet'!F60,0) -> 305703.49 | H54: =IFERROR('Data Sheet'!G60,0) -> 320179.39 | I54: =IFERROR('Data Sheet'!H60,0) -> 341569.91 | J54: =IFERROR('Data Sheet'!I60,0) -> 329061.49 | ... L54: =IFERROR('Data Sheet'!K60,0) -> 369520.61
B56: Fixed Assets Net Block | C56: =IFERROR('Data Sheet'!B61,0) -> 88479.49 | D56: =IFERROR('Data Sheet'!C61,0) -> 107231.76 | E56: =IFERROR('Data Sheet'!D61,0) -> 95944.08 | F56: =IFERROR('Data Sheet'!E61,0) -> 121413.86 | G56: =IFERROR('Data Sheet'!F61,0) -> 111234.47 | H56: =IFERROR('Data Sheet'!G61,0) -> 127107.14 | I56: =IFERROR('Data Sheet'!H61,0) -> 138707.61 | J56: =IFERROR('Data Sheet'!I61,0) -> 138855.45 | ... L56: =IFERROR('Data Sheet'!K61,0) -> 121285.46
B57: Capital Work in Progress | C57: =IFERROR('Data Sheet'!B62,0) -> 28640.09 | D57: =IFERROR('Data Sheet'!C62,0) -> 25918.94 | E57: =IFERROR('Data Sheet'!D62,0) -> 33698.84 | F57: =IFERROR('Data Sheet'!E62,0) -> 40033.5 | G57: =IFERROR('Data Sheet'!F62,0) -> 31883.84 | H57: =IFERROR('Data Sheet'!G62,0) -> 35622.29 | I57: =IFERROR('Data Sheet'!H62,0) -> 20963.93 | J57: =IFERROR('Data Sheet'!I62,0) -> 10251.09 | ... L57: =IFERROR('Data Sheet'!K62,0) -> 35698.43
B58: Investments | C58: =IFERROR('Data Sheet'!B63,0) -> 15336.74 | D58: =IFERROR('Data Sheet'!C63,0) -> 23767.02 | E58: =IFERROR('Data Sheet'!D63,0) -> 20337.92 | F58: =IFERROR('Data Sheet'!E63,0) -> 20812.75 | G58: =IFERROR('Data Sheet'!F63,0) -> 15770.72 | H58: =IFERROR('Data Sheet'!G63,0) -> 16308.48 | I58: =IFERROR('Data Sheet'!H63,0) -> 24620.28 | J58: =IFERROR('Data Sheet'!I63,0) -> 29379.53 | ... L58: =IFERROR('Data Sheet'!K63,0) -> 22971.07
B59: Other Assets | C59: =IFERROR('Data Sheet'!B64-SUM('Data Sheet'!B66:B68),0) -> 30891.17 | D59: =IFERROR('Data Sheet'!C64-SUM('Data Sheet'!C66:C68),0) -> 29579.36 | E59: =IFERROR('Data Sheet'!D64-SUM('Data Sheet'!D66:D68),0) -> 37360.78 | F59: =IFERROR('Data Sheet'!E64-SUM('Data Sheet'!E66:E68),0) -> 48286.86 | G59: =IFERROR('Data Sheet'!F64-SUM('Data Sheet'!F66:F68),0) -> 56155.74 | H59: =IFERROR('Data Sheet'!G64-SUM('Data Sheet'!G66:G68),0) -> 58784.94 | I59: =IFERROR('Data Sheet'!H64-SUM('Data Sheet'!H66:H68),0) -> 61717.96 | J59: =IFERROR('Data Sheet'!I64-SUM('Data Sheet'!I66:I68),0) -> 62223.77 | ... L59: =IFERROR('Data Sheet'!K64-SUM('Data Sheet'!K66:K68),0) -> 79018.86
B60: Total Non-Current Assets | C60: =IFERROR(SUM(C56:C59),0) -> 163347.49 | D60: =IFERROR(SUM(D56:D59),0) -> 186497.08 | E60: =IFERROR(SUM(E56:E59),0) -> 187341.62 | F60: =IFERROR(SUM(F56:F59),0) -> 230546.97 | G60: =IFERROR(SUM(G56:G59),0) -> 215044.77 | H60: =IFERROR(SUM(H56:H59),0) -> 237822.85 | I60: =IFERROR(SUM(I56:I59),0) -> 246009.78 | J60: =IFERROR(SUM(J56:J59),0) -> 240709.84 | ... L60: =IFERROR(SUM(L56:L59),0) -> 258973.82
...

Sheet Common Size Analysis
B2: ="Common Size Financial Statement Analysis"&" - "&'Data Sheet'!B1 -> Common Size Financial Statement Analysis - TATA MOTORS LTD
A4: # | B4: Common Size Balance Sheet
B6: Particulars | C6: ='Data Sheet'!B55 -> 42094 | D6: ='Data Sheet'!C55 -> 42460 | E6: ='Data Sheet'!D55 -> 42825 | F6: ='Data Sheet'!E55 -> 43190 | G6: ='Data Sheet'!F55 -> 43555 | H6: ='Data Sheet'!G55 -> 43921 | I6: ='Data Sheet'!H55 -> 44286 | J6: ='Data Sheet'!I55 -> 44651 | ... L6: ='Data Sheet'!K55 -> 45382
B8: Equity Share Capital | C8: ='Data Sheet'!B56/'Data Sheet'!B$60 -> 0.0027127681 | D8: ='Data Sheet'!C56/'Data Sheet'!C$60 -> 0.0025806268 | E8: ='Data Sheet'!D56/'Data Sheet'!D$60 -> 0.0024918156 | F8: ='Data Sheet'!E56/'Data Sheet'!E$60 -> 0.0020759077 | G8: ='Data Sheet'!F56/'Data Sheet'!F$60 -> 0.0022218261 | H8: ='Data Sheet'!G56/'Data Sheet'!G$60 -> 0.0022473027 | I8: ='Data Sheet'!H56/'Data Sheet'!H$60 -> 0.00224203 | J8: ='Data Sheet'!I56/'Data Sheet'!I$60 -> 0.0023274677 | ... L8: ='Data Sheet'!K56/'Data Sheet'!K$60 -> 0.0020743092
B9: Reserves | C9: ='Data Sheet'!B57/'Data Sheet'!B$60 -> 0.23436441 | D9: ='Data Sheet'!C57/'Data Sheet'!C$60 -> 0.29740864 | E9: ='Data Sheet'!D57/'Data Sheet'!D$60 -> 0.21051652 | F9: ='Data Sheet'!E57/'Data Sheet'!E$60 -> 0.28958148 | G9: ='Data Sheet'!F57/'Data Sheet'!F$60 -> 0.19463415 | H9: ='Data Sheet'!G57/'Data Sheet'!G$60 -> 0.19476266 | I9: ='Data Sheet'!H57/'Data Sheet'!H$60 -> 0.15950149 | J9: ='Data Sheet'!I57/'Data Sheet'!I$60 -> 0.13309172 | ... L9: ='Data Sheet'!K57/'Data Sheet'!K$60 -> 0.2277316
B10: Borrowings | C10: ='Data Sheet'!B58/'Data Sheet'!B$60 -> 0.31018037 | D10: ='Data Sheet'!C58/'Data Sheet'!C$60 -> 0.26354158 | E10: ='Data Sheet'!D58/'Data Sheet'!D$60 -> 0.28836993 | F10: ='Data Sheet'!E58/'Data Sheet'!E$60 -> 0.27186032 | G10: ='Data Sheet'!F58/'Data Sheet'!F$60 -> 0.34731478 | H10: ='Data Sheet'!G58/'Data Sheet'!G$60 -> 0.38974289 | I10: ='Data Sheet'!H58/'Data Sheet'!H$60 -> 0.41610975 | J10: ='Data Sheet'!I58/'Data Sheet'!I$60 -> 0.44505065 | ... L10: ='Data Sheet'!K58/'Data Sheet'!K$60 -> 0.29027474
B11: Other Liabilities | C11: ='Data Sheet'!B59/'Data Sheet'!B$60 -> 0.45274245 | D11: ='Data Sheet'!C59/'Data Sheet'!C$60 -> 0.43646915 | E11: ='Data Sheet'!D59/'Data Sheet'!D$60 -> 0.49862173 | F11: ='Data Sheet'!E59/'Data Sheet'!E$60 -> 0.43648229 | G11: ='Data Sheet'!F59/'Data Sheet'!F$60 -> 0.45582924 | H11: ='Data Sheet'!G59/'Data Sheet'!G$60 -> 0.41324715 | I11: ='Data Sheet'!H59/'Data Sheet'!H$60 -> 0.42214673 | J11: ='Data Sheet'!I59/'Data Sheet'!I$60 -> 0.41953016 | ... L11: ='Data Sheet'!K59/'Data Sheet'!K$60 -> 0.47991935
B12: Total Liabilities | C12: =SUM(C8:C11) -> 1 | D12: =SUM(D8:D11) -> 1 | E12: =SUM(E8:E11) -> 1 | F12: =SUM(F8:F11) -> 1 | G12: =SUM(G8:G11) -> 1 | H12: =SUM(H8:H11) -> 1 | I12: =SUM(I8:I11) -> 1 | J12: =SUM(J8:J11) -> 1 | ... L12: =SUM(L8:L11) -> 1
B14: Net Block | C14: ='Data Sheet'!B61/'Data Sheet'!B$65 -> 0.37283597 | D14: ='Data Sheet'!C61/'Data Sheet'!C$65 -> 0.40744008 | E14: ='Data Sheet'!D61/'Data Sheet'!D$65 -> 0.35198457 | F14: ='Data Sheet'!E61/'Data Sheet'!E$65 -> 0.37107854 | G14: ='Data Sheet'!F61/'Data Sheet'!F$65 -> 0.36386392 | H14: ='Data Sheet'!G61/'Data Sheet'!G$65 -> 0.39698726 | I14: ='Data Sheet'!H61/'Data Sheet'!H$65 -> 0.40608849 | J14: ='Data Sheet'!I61/'Data Sheet'!I$65 -> 0.42197417 | ... L14: ='Data Sheet'!K61/'Data Sheet'!K$65 -> 0.3282238
B15: Capital Work in Progress | C15: ='Data Sheet'!B62/'Data Sheet'!B$65 -> 0.12068397 | D15: ='Data Sheet'!C62/'Data Sheet'!C$65 -> 0.098482158 | E15: ='Data Sheet'!D62/'Data Sheet'!D$65 -> 0.12362901 | F15: ='Data Sheet'!E62/'Data Sheet'!E$65 -> 0.12235484 | G15: ='Data Sheet'!F62/'Data Sheet'!F$65 -> 0.10429662 | H15: ='Data Sheet'!G62/'Data Sheet'!G$65 -> 0.11125729 | I15: ='Data Sheet'!H62/'Data Sheet'!H$65 -> 0.061375225 | J15: ='Data Sheet'!I62/'Data Sheet'!I$65 -> 0.031152506 | ... L15: ='Data Sheet'!K62/'Data Sheet'!K$65 -> 0.096607413
B16: Investments | C16: ='Data Sheet'!B63/'Data Sheet'!B$65 -> 0.064626145 | D16: ='Data Sheet'!C63/'Data Sheet'!C$65 -> 0.090305676 | E16: ='Data Sheet'!D63/'Data Sheet'!D$65 -> 0.074612566 | F16: ='Data Sheet'!E63/'Data Sheet'!E$65 -> 0.063610241 | G16: ='Data Sheet'!F63/'Data Sheet'!F$65 -> 0.051588289 | H16: ='Data Sheet'!G63/'Data Sheet'!G$65 -> 0.050935446 | I16: ='Data Sheet'!H63/'Data Sheet'!H$65 -> 0.072079768 | J16: ='Data Sheet'!I63/'Data Sheet'!I$65 -> 0.089282796 | ... L16: ='Data Sheet'!K63/'Data Sheet'!K$65 -> 0.062164516
B17: Receivables | C17: ='Data Sheet'!B66/'Data Sheet'!B$65 -> 0.053006389 | D17: ='Data Sheet'!C66/'Data Sheet'!C$65 -> 0.051564319 | E17: ='Data Sheet'!D66/'Data Sheet'!D$65 -> 0.051638166 | F17: ='Data Sheet'!E66/'Data Sheet'!E$65 -> 0.060800116 | G17: ='Data Sheet'!F66/'Data Sheet'!F$65 -> 0.062139199 | H17: ='Data Sheet'!G66/'Data Sheet'!G$65 -> 0.034895094 | I17: ='Data Sheet'!H66/'Data Sheet'!H$65 -> 0.037120014 | J17: ='Data Sheet'!I66/'Data Sheet'!I$65 -> 0.037810927 | ... L17: ='Data Sheet'!K66/'Data Sheet'!K$65 -> 0.045875141
B18: Inventory | C18: ='Data Sheet'!B67/'Data Sheet'!B$65 -> 0.12334815 | D18: ='Data Sheet'!C67/'Data Sheet'!C$65 -> 0.12407941 | E18: ='Data Sheet'!D67/'Data Sheet'!D$65 -> 0.12871547 | F18: ='Data Sheet'!E67/'Data Sheet'!E$65 -> 0.12878571 | G18: ='Data Sheet'!F67/'Data Sheet'!F$65 -> 0.12761951 | H18: ='Data Sheet'!G67/'Data Sheet'!G$65 -> 0.11698717 | I18: ='Data Sheet'!H67/'Data Sheet'!H$65 -> 0.10565506 | J18: ='Data Sheet'!I67/'Data Sheet'!I$65 -> 0.10709348 | ... L18: ='Data Sheet'!K67/'Data Sheet'!K$65 -> 0.1293251
B19: Other Assets | C19: ='Data Sheet'!B74/'Data Sheet'!B$65 -> 0.13016959 | D19: ='Data Sheet'!C74/'Data Sheet'!C$65 -> 0.11239037 | E19: ='Data Sheet'!D74/'Data Sheet'!D$65 -> 0.13706336 | F19: ='Data Sheet'!E74/'Data Sheet'!E$65 -> 0.14757967 | G19: ='Data Sheet'!F74/'Data Sheet'!F$65 -> 0.18369349 | H19: ='Data Sheet'!G74/'Data Sheet'!G$65 -> 0.18360001 | I19: ='Data Sheet'!H74/'Data Sheet'!H$65 -> 0.1806891 | J19: ='Data Sheet'!I74/'Data Sheet'!I$65 -> 0.18909466 | ... L19: ='Data Sheet'!K74/'Data Sheet'!K$65 -> 0.21384155
B20: Cash & Bank | C20: ='Data Sheet'!B68/'Data Sheet'!B$65 -> 0.13532979 | D20: ='Data Sheet'!C68/'Data Sheet'!C$65 -> 0.11573799 | E20: ='Data Sheet'!D68/'Data Sheet'!D$65 -> 0.13235686 | F20: ='Data Sheet'!E68/'Data Sheet'!E$65 -> 0.10579088 | G20: ='Data Sheet'!F68/'Data Sheet'!F$65 -> 0.10679898 | H20: ='Data Sheet'!G68/'Data Sheet'!G$65 -> 0.10533773 | I20: ='Data Sheet'!H68/'Data Sheet'!H$65 -> 0.13699234 | J20: ='Data Sheet'!I68/'Data Sheet'!I$65 -> 0.12359146 | ... L20: ='Data Sheet'!K68/'Data Sheet'!K$65 -> 0.12396248
B21: Total Assets | C21: ='Data Sheet'!B17/'Data Sheet'!B$17 -> 1 | D21: =SUM(D14:D20) -> 1 | E21: =SUM(E14:E20) -> 1 | F21: =SUM(F14:F20) -> 1 | G21: =SUM(G14:G20) -> 1 | H21: =SUM(H14:H20) -> 1 | I21: =SUM(I14:I20) -> 1 | J21: =SUM(J14:J20) -> 1 | K21: =SUM(K14:K20) -> 1 | L21: =SUM(L14:L20) -> 1
A23: # | B23: Common Size Income Statement
B25: Particulars | C25: ='Data Sheet'!B16 -> 42094 | D25: ='Data Sheet'!C16 -> 42460 | E25: ='Data Sheet'!D16 -> 42825 | F25: ='Data Sheet'!E16 -> 43190 | G25: ='Data Sheet'!F16 -> 43555 | H25: ='Data Sheet'!G16 -> 43921 | I25: ='Data Sheet'!H16 -> 44286 | J25: ='Data Sheet'!I16 -> 44651 | ... L25: ='Data Sheet'!K16 -> 45382
B26: Sales | C26: ='Data Sheet'!B17/'Data Sheet'!B$17 -> 1 | D26: ='Data Sheet'!C17/'Data Sheet'!C$17 -> 1 | E26: ='Data Sheet'!D17/'Data Sheet'!D$17 -> 1 | F26: ='Data Sheet'!E17/'Data Sheet'!E$17 -> 1 | G26: ='Data Sheet'!F17/'Data Sheet'!F$17 -> 1 | H26: ='Data Sheet'!G17/'Data Sheet'!G$17 -> 1 | I26: ='Data Sheet'!H17/'Data Sheet'!H$17 -> 1 | J26: ='Data Sheet'!I17/'Data Sheet'!I$17 -> 1 | ... L26: ='Data Sheet'!K17/'Data Sheet'!K$17 -> 1
B27: Raw Material Cost | C27: ='Data Sheet'!B18/'Data Sheet'!B$17 -> 0.62034881 | D27: ='Data Sheet'!C18/'Data Sheet'!C$17 -> 0.60844786 | E27: ='Data Sheet'!D18/'Data Sheet'!D$17 -> 0.64256171 | F27: ='Data Sheet'!E18/'Data Sheet'!E$17 -> 0.64447357 | G27: ='Data Sheet'!F18/'Data Sheet'!F$17 -> 0.64340246 | H27: ='Data Sheet'!G18/'Data Sheet'!G$17 -> 0.63163559 | I27: ='Data Sheet'!H18/'Data Sheet'!H$17 -> 0.6149343 | J27: ='Data Sheet'!I18/'Data Sheet'!I$17 -> 0.64389657 | ... L27: ='Data Sheet'!K18/'Data Sheet'!K$17 -> 0.62640748
B28: Change in Inventory | C28: ='Data Sheet'!B19/'Data Sheet'!B$17 -> 0.012655278 | D28: ='Data Sheet'!C19/'Data Sheet'!C$17 -> 0.010075204 | E28: ='Data Sheet'!D19/'Data Sheet'!D$17 -> 0.027438359 | F28: ='Data Sheet'!E19/'Data Sheet'!E$17 -> 0.007019642 | G28: ='Data Sheet'!F19/'Data Sheet'!F$17 -> -0.0068003275 | H28: ='Data Sheet'!G19/'Data Sheet'!G$17 -> -0.008546395 | I28: ='Data Sheet'!H19/'Data Sheet'!H$17 -> -0.018752035 | J28: ='Data Sheet'!I19/'Data Sheet'!I$17 -> -0.0057118668 | ... L28: ='Data Sheet'!K19/'Data Sheet'!K$17 -> 0.0035748589
B29: Power and Fuel | C29: ='Data Sheet'!B20/'Data Sheet'!B$17 -> 0.0042626324 | D29: ='Data Sheet'!C20/'Data Sheet'!C$17 -> 0.0041884213 | E29: ='Data Sheet'!D20/'Data Sheet'!D$17 -> 0.0043005273 | F29: ='Data Sheet'!E20/'Data Sheet'!E$17 -> 0.004486633 | G29: ='Data Sheet'!F20/'Data Sheet'!F$17 -> 0.0052524952 | H29: ='Data Sheet'!G20/'Data Sheet'!G$17 -> 0.0048452899 | I29: ='Data Sheet'!H20/'Data Sheet'!H$17 -> 0.0044551377 | J29: ='Data Sheet'!I20/'Data Sheet'!I$17 -> 0.0078228109 | ... L29: ='Data Sheet'!K20/'Data Sheet'!K$17 -> 0.0050125161
B30: Other Mfr. Exp | C30: ='Data Sheet'!B21/'Data Sheet'!B$17 -> 0.061457793 | D30: ='Data Sheet'!C21/'Data Sheet'!C$17 -> 0.044320546 | E30: ='Data Sheet'!D21/'Data Sheet'!D$17 -> 0.037329068 | F30: ='Data Sheet'!E21/'Data Sheet'!E$17 -> 0.037632111 | G30: ='Data Sheet'!F21/'Data Sheet'!F$17 -> 0.038731543 | H30: ='Data Sheet'!G21/'Data Sheet'!G$17 -> 0.044208832 | I30: ='Data Sheet'!H21/'Data Sheet'!H$17 -> 0.033119871 | J30: ='Data Sheet'!I21/'Data Sheet'!I$17 -> 0.033856195 | ... L30: ='Data Sheet'!K21/'Data Sheet'!K$17 -> 0.039080257
B31: Employee Cost | C31: ='Data Sheet'!B22/'Data Sheet'!B$17 -> 0.097439008 | D31: ='Data Sheet'!C22/'Data Sheet'!C$17 -> 0.10577314 | E31: ='Data Sheet'!D22/'Data Sheet'!D$17 -> 0.10505627 | F31: ='Data Sheet'!E22/'Data Sheet'!E$17 -> 0.10392742 | G31: ='Data Sheet'!F22/'Data Sheet'!F$17 -> 0.1101015 | H31: ='Data Sheet'!G22/'Data Sheet'!G$17 -> 0.11659263 | I31: ='Data Sheet'!H22/'Data Sheet'!H$17 -> 0.11068479 | J31: ='Data Sheet'!I22/'Data Sheet'!I$17 -> 0.11064148 | ... L31: ='Data Sheet'!K22/'Data Sheet'!K$17 -> 0.09701746
B32: Selling and admin | C32: ='Data Sheet'!B23/'Data Sheet'!B$17 -> 0.089691068 | D32: ='Data Sheet'!C23/'Data Sheet'!C$17 -> 0.080542957 | E32: ='Data Sheet'!D23/'Data Sheet'!D$17 -> 0.11138381 | F32: ='Data Sheet'!E23/'Data Sheet'!E$17 -> 0.10634378 | G32: ='Data Sheet'!F23/'Data Sheet'!F$17 -> 0.10836581 | H32: ='Data Sheet'!G23/'Data Sheet'!G$17 -> 0.11203335 | I32: ='Data Sheet'!H23/'Data Sheet'!H$17 -> 0.092138806 | J32: ='Data Sheet'!I23/'Data Sheet'!I$17 -> 0.10488425 | ... L32: ='Data Sheet'!K23/'Data Sheet'!K$17 -> 0.097653844
B33: Other Expenses | C33: ='Data Sheet'!B24/'Data Sheet'!B$17 -> -0.0096502882 | D33: ='Data Sheet'!C24/'Data Sheet'!C$17 -> 0.026183832 | E33: ='Data Sheet'!D24/'Data Sheet'!D$17 -> 0.017094283 | F33: ='Data Sheet'!E24/'Data Sheet'!E$17 -> 0.0022582367 | G33: ='Data Sheet'!F24/'Data Sheet'!F$17 -> 0.0056592338 | H33: ='Data Sheet'!G24/'Data Sheet'!G$17 -> 0.013239885 | I33: ='Data Sheet'!H24/'Data Sheet'!H$17 -> -0.0033407828 | J33: ='Data Sheet'!I24/'Data Sheet'!I$17 -> 0.0044105011 | ... L33: ='Data Sheet'!K24/'Data Sheet'!K$17 -> 0.0024486001
B34: Depreciation | C34: ='Data Sheet'!B26/'Data Sheet'!B$17 -> 0.050876584 | D34: ='Data Sheet'!C26/'Data Sheet'!C$17 -> 0.061201426 | E34: ='Data Sheet'!D26/'Data Sheet'!D$17 -> 0.066390387 | F34: ='Data Sheet'!E26/'Data Sheet'!E$17 -> 0.073927472 | G34: ='Data Sheet'!F26/'Data Sheet'!F$17 -> 0.078130605 | H34: ='Data Sheet'!G26/'Data Sheet'!G$17 -> 0.082068398 | I34: ='Data Sheet'!H26/'Data Sheet'!H$17 -> 0.094264231 | J34: ='Data Sheet'!I26/'Data Sheet'!I$17 -> 0.089191478 | ... L34: ='Data Sheet'!K26/'Data Sheet'!K$17 -> 0.06227084
B35: Interest | C35: ='Data Sheet'!B27/'Data Sheet'!B$17 -> 0.018473586 | D35: ='Data Sheet'!C27/'Data Sheet'!C$17 -> 0.017905727 | E35: ='Data Sheet'!D27/'Data Sheet'!D$17 -> 0.01571423 | F35: ='Data Sheet'!E27/'Data Sheet'!E$17 -> 0.016058248 | G35: ='Data Sheet'!F27/'Data Sheet'!F$17 -> 0.019072102 | H35: ='Data Sheet'!G27/'Data Sheet'!G$17 -> 0.027744997 | I35: ='Data Sheet'!H27/'Data Sheet'!H$17 -> 0.032415293 | J35: ='Data Sheet'!I27/'Data Sheet'!I$17 -> 0.033441332 | ... L35: ='Data Sheet'!K27/'Data Sheet'!K$17 -> 0.022802299
B36: Profit before tax | C36: ='Data Sheet'!B28/'Data Sheet'!B$17 -> 0.082469388 | D36: ='Data Sheet'!C28/'Data Sheet'!C$17 -> 0.051734106 | E36: ='Data Sheet'!D28/'Data Sheet'!D$17 -> 0.034538557 | F36: ='Data Sheet'!E28/'Data Sheet'!E$17 -> 0.038261059 | G36: ='Data Sheet'!F28/'Data Sheet'!F$17 -> -0.10389917 | H36: ='Data Sheet'!G28/'Data Sheet'!G$17 -> -0.040525768 | I36: ='Data Sheet'!H28/'Data Sheet'!H$17 -> -0.041931546 | J36: ='Data Sheet'!I28/'Data Sheet'!I$17 -> -0.025151083 | ... L36: ='Data Sheet'!K28/'Data Sheet'!K$17 -> 0.063834979
B37: Tax | C37: ='Data Sheet'!B29/'Data Sheet'!B$17 -> 0.029042938 | D37: ='Data Sheet'!C29/'Data Sheet'!C$17 -> 0.011078919 | E37: ='Data Sheet'!D29/'Data Sheet'!D$17 -> 0.012055322 | F37: ='Data Sheet'!E29/'Data Sheet'!E$17 -> 0.01489255 | G37: ='Data Sheet'!F29/'Data Sheet'!F$17 -> -0.0080726731 | H37: ='Data Sheet'!G29/'Data Sheet'!G$17 -> 0.0015139735 | I37: ='Data Sheet'!H29/'Data Sheet'!H$17 -> 0.010175794 | J37: ='Data Sheet'!I29/'Data Sheet'!I$17 -> 0.015195672 | ... L37: ='Data Sheet'!K29/'Data Sheet'!K$17 -> -0.008795149
B38: Net profit | C38: ='Data Sheet'!B30/'Data Sheet'!B$17 -> 0.053147683 | D38: ='Data Sheet'!C30/'Data Sheet'!C$17 -> 0.042407971 | E38: ='Data Sheet'!D30/'Data Sheet'!D$17 -> 0.027640219 | F38: ='Data Sheet'!E30/'Data Sheet'!E$17 -> 0.030831402 | G38: ='Data Sheet'!F30/'Data Sheet'!F$17 -> -0.095470566 | H38: ='Data Sheet'!G30/'Data Sheet'!G$17 -> -0.046236426 | I38: ='Data Sheet'!H30/'Data Sheet'!H$17 -> -0.053849771 | J38: ='Data Sheet'!I30/'Data Sheet'!I$17 -> -0.04108932 | ... L38: ='Data Sheet'!K30/'Data Sheet'!K$17 -> 0.071699244
B39: EBITDA | C39: ='Data Sheet'!B34/'Data Sheet'!B$17 -> 0.15154079 | D39: ='Data Sheet'!C34/'Data Sheet'!C$17 -> 0.13259404 | E39: ='Data Sheet'!D34/'Data Sheet'!D$17 -> 0.12180016 | F39: ='Data Sheet'!E34/'Data Sheet'!E$17 -> 0.13570967 | G39: ='Data Sheet'!F34/'Data Sheet'!F$17 -> -0.0063405317 | H39: ='Data Sheet'!G34/'Data Sheet'!G$17 -> 0.065090942 | I39: ='Data Sheet'!H34/'Data Sheet'!H$17 -> 0.083005548 | J39: ='Data Sheet'!I34/'Data Sheet'!I$17 -> 0.096739163 | ... L39: ='Data Sheet'!K34/'Data Sheet'!K$17 -> 0.14797723

Sheet Ratio Analysis
B2: ="Ratio Analysis - "&'Data Sheet'!B1 -> Ratio Analysis - TATA MOTORS LTD
B3: Year | C3: ='Data Sheet'!B16 -> 42094 | D3: ='Data Sheet'!C16 -> 42460 | E3: ='Data Sheet'!D16 -> 42825 | F3: ='Data Sheet'!E16 -> 43190 | G3: ='Data Sheet'!F16 -> 43555 | H3: ='Data Sheet'!G16 -> 43921 | I3: ='Data Sheet'!H16 -> 44286 | J3: ='Data Sheet'!I16 -> 44651 | ... L3: ='Data Sheet'!K16 -> 45382 | M3: Trend | N3: Mean | O3: Median
B6: SalesGrowth | D6: =IFERROR('Historical FS'!D7,0) -> 0.037569001 | E6: =IFERROR('Historical FS'!E7,0) -> -0.01228033 | F6: =IFERROR('Historical FS'!F7,0) -> 0.081047746 | G6: =IFERROR('Historical FS'!G7,0) -> 0.035629919 | H6: =IFERROR('Historical FS'!H7,0) -> -0.13536016 | I6: =IFERROR('Historical FS'!I7,0) -> -0.043181168 | J6: =IFERROR('Historical FS'!J7,0) -> 0.11472967 | K6: =IFERROR('Historical FS'!K7,0) -> 0.24245815 | L6: =IFERROR('Historical FS'!L7,0) -> 0.26580803 | N6: =IFERROR(AVERAGE(D6:L6),0) -> 0.065157874 | O6: =IFERROR(MEDIAN(C6:L6),0) -> 0.037569001
B7: EBITDA Growth | D7: =IFERROR('Historical FS'!D18/'Historical FS'!C18-1,0) -> -0.021494114 | E7: =IFERROR('Historical FS'!E18/'Historical FS'!D18-1,0) -> -0.22936587 | F7: =IFERROR('Historical FS'!F18/'Historical FS'!E18-1,0) -> 0.063165689 | G7: =IFERROR('Historical FS'!G18/'Historical FS'!F18-1,0) -> -0.21595203 | H7: =IFERROR('Historical FS'!H18/'Historical FS'!G18-1,0) -> -0.27072538 | I7: =IFERROR('Historical FS'!I18/'Historical FS'!H18-1,0) -> 0.79503554 | J7: =IFERROR('Historical FS'!J18/'Historical FS'!I18-1,0) -> -0.23437418 | K7: =IFERROR('Historical FS'!K18/'Historical FS'!J18-1,0) -> 0.28704224 | L7: =IFERROR('Historical FS'!L18/'Historical FS'!K18-1,0) -> 0.87134505 | N7: =IFERROR(AVERAGE(D7:L7),0) -> 0.11607522 | O7: =IFERROR(MEDIAN(C7:L7),0) -> -0.021494114
B8: EBIT Growth | D8: =IFERROR(('Historical FS'!D18-'Historical FS'!D24)/('Historical FS'!C18-'Historical FS'!C24)-1,0) -> -0.16114301 | E8: =IFERROR(('Historical FS'!E18-'Historical FS'!E24)/('Historical FS'!D18-'Historical FS'!D24)-1,0) -> -0.46119504 | F8: =IFERROR(('Historical FS'!F18-'Historical FS'!F24)/('Historical FS'!E18-'Historical FS'!E24)-1,0) -> -0.15231562 | G8: =IFERROR(('Historical FS'!G18-'Historical FS'!G24)/('Historical FS'!F18-'Historical FS'!F24)-1,0) -> -0.89159024 | H8: =IFERROR(('Historical FS'!H18-'Historical FS'!H24)/('Historical FS'!G18-'Historical FS'!G24)-1,0) -> -4.202347 | I8: =IFERROR(('Historical FS'!I18-'Historical FS'!I24)/('Historical FS'!H18-'Historical FS'!H24)-1,0) -> -3.5421189 | J8: =IFERROR(('Historical FS'!J18-'Historical FS'!J24)/('Historical FS'!I18-'Historical FS'!I24)-1,0) -> -1.0132255 | K8: =IFERROR(('Historical FS'!K18-'Historical FS'!K24)/('Historical FS'!J18-'Historical FS'!J24)-1,0) -> -61.168166 | L8: =IFERROR(('Historical FS'!L18-'Historical FS'!L24)/('Historical FS'!K18-'Historical FS'!K24)-1,0) -> 3.6392766 | N8: =IFERROR(AVERAGE(D8:L8),0) -> -7.5503139 | O8: =IFERROR(MEDIAN(C8:L8),0) -> -0.89159024
B9: EBT Growth | D9: =IFERROR('Historical FS'!D27/'Historical FS'!C27-1,0) -> -0.19978245 | E9: =IFERROR('Historical FS'!E27/'Historical FS'!D27-1,0) -> -0.55668252 | F9: =IFERROR('Historical FS'!F27/'Historical FS'!E27-1,0) -> -0.29861437 | G9: =IFERROR('Historical FS'!G27/'Historical FS'!F27-1,0) -> -1.8970951 | H9: =IFERROR('Historical FS'!H27/'Historical FS'!G27-1,0) -> 1.2800252 | I9: =IFERROR('Historical FS'!I27/'Historical FS'!H27-1,0) -> -1.060248 | J9: =IFERROR('Historical FS'!J27/'Historical FS'!I27-1,0) -> -15.649149 | K9: =IFERROR('Historical FS'!K27/'Historical FS'!J27-1,0) -> -0.65313669 | L9: =IFERROR('Historical FS'!L27/'Historical FS'!K27-1,0) -> -7.8141215 | N9: =IFERROR(AVERAGE(D9:L9),0) -> -2.9832005 | O9: =IFERROR(MEDIAN(C9:L9),0) -> -0.65313669
B10: Net Profit Growth | D10: =IFERROR('Historical FS'!D33/'Historical FS'!C33-1,0) -> 0.031824674 | E10: =IFERROR('Historical FS'!E33/'Historical FS'!D33-1,0) -> -0.69539895 | F10: =IFERROR('Historical FS'!F33/'Historical FS'!E33-1,0) -> -0.79011124 | G10: =IFERROR('Historical FS'!G33/'Historical FS'!F33-1,0) -> -3.5528471 | H10: =IFERROR('Historical FS'!H33/'Historical FS'!G33-1,0) -> 3.9286703 | I10: =IFERROR('Historical FS'!I33/'Historical FS'!H33-1,0) -> -0.82862505 | J10: =IFERROR('Historical FS'!J33/'Historical FS'!I33-1,0) -> 6.1952157 | K10: =IFERROR('Historical FS'!K33/'Historical FS'!J33-1,0) -> -0.70904365 | L10: =IFERROR('Historical FS'!L33/'Historical FS'!K33-1,0) -> -7.5761028 | N10: =IFERROR(AVERAGE(D10:L10),0) -> -0.44404645 | O10: =IFERROR(MEDIAN(C10:L10),0) -> -0.70904365
B11: Dividend Growth | D11: =IFERROR('Historical FS'!D42/'Historical FS'!C42-1,0) -> 0 | E11: =IFERROR('Historical FS'!E42/'Historical FS'!D42-1,0) -> -1 | F11: =IFERROR('Historical FS'!F42/'Historical FS'!E42-1,0) -> 0 | G11: =IFERROR('Historical FS'!G42/'Historical FS'!F42-1,0) -> 0 | H11: =IFERROR('Historical FS'!H42/'Historical FS'!G42-1,0) -> 0 | I11: =IFERROR('Historical FS'!I42/'Historical FS'!H42-1,0) -> 0 | J11: =IFERROR('Historical FS'!J42/'Historical FS'!I42-1,0) -> 0 | K11: =IFERROR('Historical FS'!K42/'Historical FS'!J42-1,0) -> 0 | L11: =IFERROR('Historical FS'!L42/'Historical FS'!K42-1,0) -> 1.9997122 | N11: =IFERROR(AVERAGE(D11:L11),0) -> 0.11107914 | O11: =IFERROR(MEDIAN(C11:L11),0) -> 0
B13: Gross Margin | C13: =IFERROR('Historical FS'!C13,0) -> 0.22914703 | D13: =IFERROR('Historical FS'!D13,0) -> 0.24734524 | E13: =IFERROR('Historical FS'!E13,0) -> 0.23819078 | F13: =IFERROR('Historical FS'!F13,0) -> 0.2164999 | G13: =IFERROR('Historical FS'!G13,0) -> 0.19571167 | H13: =IFERROR('Historical FS'!H13,0) -> 0.19417127 | I13: =IFERROR('Historical FS'!I13,0) -> 0.21805386 | J13: =IFERROR('Historical FS'!J13,0) -> 0.19807108 | ... L13: =IFERROR('Historical FS'!L13,0) -> 0.23605715 | N13: =IFERROR(AVERAGE(C13:L13),0) -> 0.21800982 | O13: =IFERROR(MEDIAN(C13:L13),0) -> 0.21727688
B14: EBITDA Margin | C14: =IFERROR('Historical FS'!C19,0) -> 0.14910626 | D14: =IFERROR('Historical FS'!D19,0) -> 0.14061845 | E14: =IFERROR('Historical FS'!E19,0) -> 0.10971269 | F14: =IFERROR('Historical FS'!F19,0) -> 0.10789788 | G14: =IFERROR('Historical FS'!G19,0) -> 0.081686629 | H14: =IFERROR('Historical FS'!H19,0) -> 0.068898034 | I14: =IFERROR('Historical FS'!I19,0) -> 0.12925584 | J14: =IFERROR('Historical FS'!J19,0) -> 0.088776328 | ... L14: =IFERROR('Historical FS'!L19,0) -> 0.1359547 | N14: =IFERROR(AVERAGE(C14:L14),0) -> 0.11038688 | O14: =IFERROR(MEDIAN(C14:L14),0) -> 0.10880529
B15: EBIT Margin | C15: =IFERROR(('Historical FS'!C18-'Historical FS'!C24)/'Historical FS'!C6,0) -> 0.098229671 | D15: =IFERROR(('Historical FS'!D18-'Historical FS'!D24)/'Historical FS'!D6,0) -> 0.079417028 | E15: =IFERROR(('Historical FS'!E18-'Historical FS'!E24)/'Historical FS'!E6,0) -> 0.043322301 | F15: =IFERROR(('Historical FS'!F18-'Historical FS'!F24)/'Historical FS'!F6,0) -> 0.033970412 | G15: =IFERROR(('Historical FS'!G18-'Historical FS'!G24)/'Historical FS'!G6,0) -> 0.0035560233 | H15: =IFERROR(('Historical FS'!H18-'Historical FS'!H24)/'Historical FS'!H6,0) -> -0.013170363 | I15: =IFERROR(('Historical FS'!I18-'Historical FS'!I24)/'Historical FS'!I6,0) -> 0.034991608 | J15: =IFERROR(('Historical FS'!J18-'Historical FS'!J24)/'Historical FS'!J6,0) -> -0.00041514993 | ... L15: =IFERROR(('Historical FS'!L18-'Historical FS'!L24)/'Historical FS'!L6,0) -> 0.073683863 | N15: =IFERROR(AVERAGE(C15:L15),0) -> 0.037368974 | O15: =IFERROR(MEDIAN(C15:L15),0) -> 0.03448101
B16: EBT Margin | C16: =IFERROR('Historical FS'!C28,0) -> 0.079756085 | D16: =IFERROR('Historical FS'!D28,0) -> 0.061511301 | E16: =IFERROR('Historical FS'!E28,0) -> 0.027608071 | F16: =IFERROR('Historical FS'!F28,0) -> 0.017912164 | G16: =IFERROR('Historical FS'!G28,0) -> -0.015516079 | H16: =IFERROR('Historical FS'!H28,0) -> -0.04091536 | I16: =IFERROR('Historical FS'!I28,0) -> 0.0025763152 | J16: =IFERROR('Historical FS'!J28,0) -> -0.033856482 | ... L16: =IFERROR('Historical FS'!L28,0) -> 0.050881564 | N16: =IFERROR(AVERAGE(C16:L16),0) -> 0.014050569 | O16: =IFERROR(MEDIAN(C16:L16),0) -> 0.01024424
B17: Net Profit Margin | C17: =IFERROR('Historical FS'!C34,0) -> 0.050713147 | D17: =IFERROR('Historical FS'!D34,0) -> 0.050432382 | E17: =IFERROR('Historical FS'!E34,0) -> 0.015552749 | F17: =IFERROR('Historical FS'!F34,0) -> 0.0030196143 | G17: =IFERROR('Historical FS'!G34,0) -> -0.0074434057 | H17: =IFERROR('Historical FS'!H34,0) -> -0.042429334 | I17: =IFERROR('Historical FS'!I34,0) -> -0.0075994792 | J17: =IFERROR('Historical FS'!J34,0) -> -0.049052155 | ... L17: =IFERROR('Historical FS'!L34,0) -> 0.059676713 | N17: =IFERROR(AVERAGE(C17:L17),0) -> 0.0061383298 | O17: =IFERROR(MEDIAN(C17:L17),0) -> -0.0022118957
B19: SalesExpenses%Sales | C19: =IFERROR('Historical FS'!C16,0) -> 0.08004078 | D19: =IFERROR('Historical FS'!D16,0) -> 0.10672679 | E19: =IFERROR('Historical FS'!E16,0) -> 0.1284781 | F19: =IFERROR('Historical FS'!F16,0) -> 0.10860202 | G19: =IFERROR('Historical FS'!G16,0) -> 0.11402505 | H19: =IFERROR('Historical FS'!H16,0) -> 0.12527324 | I19: =IFERROR('Historical FS'!I16,0) -> 0.088798023 | J19: =IFERROR('Historical FS'!J16,0) -> 0.10929475 | ... L19: =IFERROR('Historical FS'!L16,0) -> 0.10010244 | N19: =IFERROR(AVERAGE(C19:L19),0) -> 0.10762294 | O19: =IFERROR(MEDIAN(C19:L19),0) -> 0.10894839
B20: Depreciation%Sales | C20: =IFERROR('Historical FS'!C25,0) -> 0.050876584 | D20: =IFERROR('Historical FS'!D25,0) -> 0.061201426 | E20: =IFERROR('Historical FS'!E25,0) -> 0.066390387 | F20: =IFERROR('Historical FS'!F25,0) -> 0.073927472 | G20: =IFERROR('Historical FS'!G25,0) -> 0.078130605 | H20: =IFERROR('Historical FS'!H25,0) -> 0.082068398 | I20: =IFERROR('Historical FS'!I25,0) -> 0.094264231 | J20: =IFERROR('Historical FS'!J25,0) -> 0.089191478 | ... L20: =IFERROR('Historical FS'!L25,0) -> 0.06227084 | N20: =IFERROR(AVERAGE(C20:L20),0) -> 0.073017903 | O20: =IFERROR(MEDIAN(C20:L20),0) -> 0.072892542
B21: OperatingIncome%Sales | C21: =C15 -> 0.098229671 | D21: =D15 -> 0.079417028 | E21: =E15 -> 0.043322301 | F21: =F15 -> 0.033970412 | G21: =G15 -> 0.0035560233 | H21: =H15 -> -0.013170363 | I21: =I15 -> 0.034991608 | J21: =J15 -> -0.00041514993 | ... L21: =L15 -> 0.073683863 | N21: =IFERROR(AVERAGE(C21:L21),0) -> 0.037368974 | O21: =IFERROR(MEDIAN(C21:L21),0) -> 0.03448101
B23: Return on Capital Employed | C23: =IFERROR(('Historical FS'!C18-'Historical FS'!C24)/(SUM('Historical FS'!C50:C52)),0) -> 0.19904181 | D23: =IFERROR(('Historical FS'!D18-'Historical FS'!D24)/(SUM('Historical FS'!D50:D52)),0) -> 0.1462081 | E23: =IFERROR(('Historical FS'!E18-'Historical FS'!E24)/(SUM('Historical FS'!E50:E52)),0) -> 0.085490986 | F23: =IFERROR(('Historical FS'!F18-'Historical FS'!F24)/(SUM('Historical FS'!F50:F52)),0) -> 0.053716114 | G23: =IFERROR(('Historical FS'!G18-'Historical FS'!G24)/(SUM('Historical FS'!G50:G52)),0) -> 0.0064542734 | H23: =IFERROR(('Historical FS'!H18-'Historical FS'!H24)/(SUM('Historical FS'!H50:H52)),0) -> -0.018302178 | I23: =IFERROR(('Historical FS'!I18-'Historical FS'!I24)/(SUM('Historical FS'!I50:I52)),0) -> 0.044284325 | J23: =IFERROR(('Historical FS'!J18-'Historical FS'!J24)/(SUM('Historical FS'!J50:J52)),0) -> -0.00060520306 | ... L23: =IFERROR(('Historical FS'!L18-'Historical FS'!L24)/(SUM('Historical FS'!L50:L52)),0) -> 0.16790573 | N23: =IFERROR(AVERAGE(C23:L23),0) -> 0.072295691 | O23: =IFERROR(MEDIAN(C23:L23),0) -> 0.049000219
B24: Retained Earnings% | C24: =IFERROR('Historical FS'!C45,0) -> 1 | D24: =IFERROR('Historical FS'!D45,0) -> 0.99506766 | E24: =IFERROR('Historical FS'!E45,0) -> 1 | F24: =IFERROR('Historical FS'!F45,0) -> 1 | G24: =IFERROR('Historical FS'!G45,0) -> 0 | H24: =IFERROR('Historical FS'!H45,0) -> 0 | I24: =IFERROR('Historical FS'!I45,0) -> 0 | J24: =IFERROR('Historical FS'!J45,0) -> 0 | ... L24: =IFERROR('Historical FS'!L45,0) -> 0.91201148 | N24: =IFERROR(AVERAGE(C24:L24),0) -> 0.49070791 | O24: =IFERROR(MEDIAN(C24:L24),0) -> 0.45600574
B25: Return on Equity% | C25: =IFERROR('Historical FS'!C33/(SUM('Historical FS'!C50:C51)),0) -> 0.2372052 | D25: =IFERROR('Historical FS'!D33/(SUM('Historical FS'!D50:D51)),0) -> 0.17441317 | E25: =IFERROR('Historical FS'!E33/(SUM('Historical FS'!E50:E51)),0) -> 0.07224119 | F25: =IFERROR('Historical FS'!F33/(SUM('Historical FS'!F50:F51)),0) -> 0.0092254981 | G25: =IFERROR('Historical FS'!G33/(SUM('Historical FS'!G50:G51)),0) -> -0.037345737 | H25: =IFERROR('Historical FS'!H33/(SUM('Historical FS'!H50:H51)),0) -> -0.17560555 | I25: =IFERROR('Historical FS'!I33/(SUM('Historical FS'!I50:I51)),0) -> -0.034360592 | J25: =IFERROR('Historical FS'!J33/(SUM('Historical FS'!J50:J51)),0) -> -0.30651638 | ... L25: =IFERROR('Historical FS'!L33/(SUM('Historical FS'!L50:L51)),0) -> 0.3077567 | N25: =IFERROR(AVERAGE(C25:L25),0) -> 0.01593272 | O25: =IFERROR(MEDIAN(C25:L25),0) -> -0.012567547
B26: Self Sustained Growth Rate | C26: =IFERROR(C24*C25,0) -> 0.2372052 | D26: =IFERROR(D24*D25,0) -> 0.1735529 | E26: =IFERROR(E24*E25,0) -> 0.07224119 | F26: =IFERROR(F24*F25,0) -> 0.0092254981 | G26: =IFERROR(G24*G25,0) -> 0 | H26: =IFERROR(H24*H25,0) -> 0 | I26: =IFERROR(I24*I25,0) -> 0 | J26: =IFERROR(J24*J25,0) -> 0 | ... L26: =IFERROR(L24*L25,0) -> 0.28067765 | N26: =IFERROR(AVERAGE(C26:L26),0) -> 0.077290244 | O26: =IFERROR(MEDIAN(C26:L26),0) -> 0.004612749
B27: Interest Coverage Ratio | C27: =IFERROR(('Historical FS'!C18-'Historical FS'!C24)/'Historical FS'!C21,0) -> 5.317304 | D27: =IFERROR(('Historical FS'!D18-'Historical FS'!D24)/'Historical FS'!D21,0) -> 4.4352864 | E27: =IFERROR(('Historical FS'!E18-'Historical FS'!E24)/'Historical FS'!E21,0) -> 2.7568835 | F27: =IFERROR(('Historical FS'!F18-'Historical FS'!F24)/'Historical FS'!F21,0) -> 2.1154494 | G27: =IFERROR(('Historical FS'!G18-'Historical FS'!G24)/'Historical FS'!G21,0) -> 0.18645157 | H27: =IFERROR(('Historical FS'!H18-'Historical FS'!H24)/'Historical FS'!H21,0) -> -0.47469327 | I27: =IFERROR(('Historical FS'!I18-'Historical FS'!I24)/'Historical FS'!I21,0) -> 1.0794784 | J27: =IFERROR(('Historical FS'!J18-'Historical FS'!J24)/'Historical FS'!J21,0) -> -0.012414276 | ... L27: =IFERROR(('Historical FS'!L18-'Historical FS'!L24)/'Historical FS'!L21,0) -> 3.2314225 | N27: =IFERROR(AVERAGE(C27:L27),0) -> 1.9315375 | O27: =IFERROR(MEDIAN(C27:L27),0) -> 1.5974639
B29: Debtor Turnover Ratio | C29: =IFERROR('Historical FS'!C6/'Historical FS'!C62,0) -> 20.920168 | D29: =IFERROR('Historical FS'!D6/'Historical FS'!D62,0) -> 20.119918 | E29: =IFERROR('Historical FS'!E6/'Historical FS'!E62,0) -> 19.160353 | F29: =IFERROR('Historical FS'!F6/'Historical FS'!F62,0) -> 14.655712 | G29: =IFERROR('Historical FS'!G6/'Historical FS'!G62,0) -> 15.894699 | H29: =IFERROR('Historical FS'!H6/'Historical FS'!H62,0) -> 23.366617 | I29: =IFERROR('Historical FS'!I6/'Historical FS'!I62,0) -> 19.701331 | J29: =IFERROR('Historical FS'!J6/'Historical FS'!J62,0) -> 22.379918 | ... L29: =IFERROR('Historical FS'!L6/'Historical FS'!L62,0) -> 25.833688 | N29: =IFERROR(AVERAGE(C29:L29),0) -> 20.401535 | O29: =IFERROR(MEDIAN(C29:L29),0) -> 20.520043
B30: Creditor Turnover Ratio | C30: =IFERROR('Historical FS'!C6/'Historical FS'!C53,0) -> 2.4493011 | D30: =IFERROR('Historical FS'!D6/'Historical FS'!D53,0) -> 2.3769604 | E30: =IFERROR('Historical FS'!E6/'Historical FS'!E53,0) -> 1.9842808 | F30: =IFERROR('Historical FS'!F6/'Historical FS'!F53,0) -> 2.041478 | G30: =IFERROR('Historical FS'!G6/'Historical FS'!G53,0) -> 2.1667848 | H30: =IFERROR('Historical FS'!H6/'Historical FS'!H53,0) -> 1.9731057 | I30: =IFERROR('Historical FS'!I6/'Historical FS'!I53,0) -> 1.7323685 | J30: =IFERROR('Historical FS'!J6/'Historical FS'!J53,0) -> 2.0170312 | ... L30: =IFERROR('Historical FS'!L6/'Historical FS'!L53,0) -> 2.4694234 | N30: =IFERROR(AVERAGE(C30:L30),0) -> 2.143934 | O30: =IFERROR(MEDIAN(C30:L30),0) -> 2.1041314
B31: Inventory Turnover | C31: =IFERROR('Historical FS'!C9/'Historical FS'!C63,0) -> 6.9299851 | D31: =IFERROR('Historical FS'!D9/'Historical FS'!D63,0) -> 6.2932009 | E31: =IFERROR('Historical FS'!E9/'Historical FS'!E63,0) -> 5.8558479 | F31: =IFERROR('Historical FS'!F9/'Historical FS'!F63,0) -> 5.4210412 | G31: =IFERROR('Historical FS'!G9/'Historical FS'!G63,0) -> 6.2246171 | H31: =IFERROR('Historical FS'!H9/'Historical FS'!H63,0) -> 5.6164867 | I31: =IFERROR('Historical FS'!I9/'Historical FS'!I63,0) -> 5.4124043 | J31: =IFERROR('Historical FS'!J9/'Historical FS'!J63,0) -> 6.3364885 | ... L31: =IFERROR('Historical FS'!L9/'Historical FS'!L63,0) -> 7.0007064 | N31: =IFERROR(AVERAGE(C31:L31),0) -> 6.1823719 | O31: =IFERROR(MEDIAN(C31:L31),0) -> 6.258909
B32: Fixed Asset Turnover | C32: =IFERROR('Historical FS'!C6/'Historical FS'!C56,0) -> 2.9742371 | D32: =IFERROR('Historical FS'!D6/'Historical FS'!D56,0) -> 2.5463128 | E32: =IFERROR('Historical FS'!E6/'Historical FS'!E56,0) -> 2.8109343 | F32: =IFERROR('Historical FS'!F6/'Historical FS'!F56,0) -> 2.4012949 | G32: =IFERROR('Historical FS'!G6/'Historical FS'!G56,0) -> 2.714432 | H32: =IFERROR('Historical FS'!H6/'Historical FS'!H56,0) -> 2.0539206 | I32: =IFERROR('Historical FS'!I6/'Historical FS'!I56,0) -> 1.8008727 | J32: =IFERROR('Historical FS'!J6/'Historical FS'!J56,0) -> 2.0053489 | ... L32: =IFERROR('Historical FS'!L6/'Historical FS'!L56,0) -> 3.6107195 | N32: =IFERROR(AVERAGE(C32:L32),0) -> 2.5537452 | O32: =IFERROR(MEDIAN(C32:L32),0) -> 2.582846
B33: Capital Turnover Ratio | C33: =IFERROR('Historical FS'!C6/(SUM('Historical FS'!C50:C51)),0) -> 4.6773907 | D33: =IFERROR('Historical FS'!D6/(SUM('Historical FS'!D50:D51)),0) -> 3.4583567 | E33: =IFERROR('Historical FS'!E6/(SUM('Historical FS'!E50:E51)),0) -> 4.6449144 | F33: =IFERROR('Historical FS'!F6/(SUM('Historical FS'!F50:F51)),0) -> 3.0551909 | G33: =IFERROR('Historical FS'!G6/(SUM('Historical FS'!G50:G51)),0) -> 5.0172916 | H33: =IFERROR('Historical FS'!H6/(SUM('Historical FS'!H50:H51)),0) -> 4.138777 | I33: =IFERROR('Historical FS'!I6/(SUM('Historical FS'!I50:I51)),0) -> 4.5214404 | J33: =IFERROR('Historical FS'!J6/(SUM('Historical FS'!J50:J51)),0) -> 6.2487853 | ... L33: =IFERROR('Historical FS'!L6/(SUM('Historical FS'!L50:L51)),0) -> 5.1570652 | N33: =IFERROR(AVERAGE(C33:L33),0) -> 4.855278 | O33: =IFERROR(MEDIAN(C33:L33),0) -> 4.6611525
B35: ( In Days )
B36: Debtor Days | C36: =IFERROR(365/C29,0) -> 17.447278 | D36: =IFERROR(365/D29,0) -> 18.141227 | E36: =IFERROR(365/E29,0) -> 19.049753 | F36: =IFERROR(365/F29,0) -> 24.904965 | G36: =IFERROR(365/G29,0) -> 22.963631 | H36: =IFERROR(365/H29,0) -> 15.620575 | I36: =IFERROR(365/I29,0) -> 18.526667 | J36: =IFERROR(365/J29,0) -> 16.309265 | ... L36: =IFERROR(365/L29,0) -> 14.128838 | N36: =IFERROR(AVERAGE(C36:L36),0) -> 18.369598 | O36: =IFERROR(MEDIAN(C36:L36),0) -> 17.794253
B37: Payable Days | C37: =IFERROR(365/C30,0) -> 149.02211 | D37: =IFERROR(365/D30,0) -> 153.55746 | E37: =IFERROR(365/E30,0) -> 183.94574 | F37: =IFERROR(365/F30,0) -> 178.79203 | G37: =IFERROR(365/G30,0) -> 168.45236 | H37: =IFERROR(365/H30,0) -> 184.98755 | I37: =IFERROR(365/I30,0) -> 210.69421 | J37: =IFERROR(365/J30,0) -> 180.95902 | ... L37: =IFERROR(365/L30,0) -> 147.80778 | N37: =IFERROR(AVERAGE(C37:L37),0) -> 172.19978 | O37: =IFERROR(MEDIAN(C37:L37),0) -> 173.62219
B38: Inventory Days | C38: =IFERROR(365/C31,0) -> 52.669666 | D38: =IFERROR(365/D31,0) -> 57.999102 | E38: =IFERROR(365/E31,0) -> 62.330854 | F38: =IFERROR(365/F31,0) -> 67.330239 | G38: =IFERROR(365/G31,0) -> 58.638145 | H38: =IFERROR(365/H31,0) -> 64.987245 | I38: =IFERROR(365/I31,0) -> 67.437682 | J38: =IFERROR(365/J31,0) -> 57.602882 | ... L38: =IFERROR(365/L31,0) -> 52.137595 | N38: =IFERROR(AVERAGE(C38:L38),0) -> 59.534449 | O38: =IFERROR(MEDIAN(C38:L38),0) -> 58.318623
B39: Cash Conversion Cycle | C39: =IFERROR(SUM(C36,C38)-C37,0) -> -78.905161 | D39: =IFERROR(SUM(D36,D38)-D37,0) -> -77.417131 | E39: =IFERROR(SUM(E36,E38)-E37,0) -> -102.56514 | F39: =IFERROR(SUM(F36,F38)-F37,0) -> -86.556826 | G39: =IFERROR(SUM(G36,G38)-G37,0) -> -86.850581 | H39: =IFERROR(SUM(H36,H38)-H37,0) -> -104.37973 | I39: =IFERROR(SUM(I36,I38)-I37,0) -> -124.72986 | J39: =IFERROR(SUM(J36,J38)-J37,0) -> -107.04688 | ... L39: =IFERROR(SUM(L36,L38)-L37,0) -> -81.541349 | N39: =IFERROR(AVERAGE(C39:L39),0) -> -94.295732 | O39: =IFERROR(MEDIAN(C39:L39),0) -> -89.907627
B41: CFO/Sales | C41: =IFERROR('Historical FS'!C81/'Historical FS'!C6,0) -> 0.1210675 | D41: =IFERROR('Historical FS'!D81/'Historical FS'!D6,0) -> 0.14360971 | E41: =IFERROR('Historical FS'!E81/'Historical FS'!E6,0) -> 0.12404497 | F41: =IFERROR('Historical FS'!F81/'Historical FS'!F6,0) -> 0.059759806 | G41: =IFERROR('Historical FS'!G81/'Historical FS'!G6,0) -> 0.03865358 | H41: =IFERROR('Historical FS'!H81/'Historical FS'!H6,0) -> 0.12141666 | I41: =IFERROR('Historical FS'!I81/'Historical FS'!I6,0) -> 0.11572301 | J41: =IFERROR('Historical FS'!J81/'Historical FS'!J6,0) -> 0.012684339 | ... L41: =IFERROR('Historical FS'!L81/'Historical FS'!L6,0) -> 0.17181144 | N41: =IFERROR(AVERAGE(C41:L41),0) -> 0.10020198 | O41: =IFERROR(MEDIAN(C41:L41),0) -> 0.11839525
